INFO  | File generate_dummy_article.py | Line 33    | Writing log file to /home/jovyan/llm_risk_management/src/logs/log_0831_162130
INFO  | File generate_dummy_article.py | Line 34    | Exp instance id = 0831_162130
ERROR | File generate_dummy_article.py | Line 76    | Traceback (most recent call last):
  File "/opt/conda/lib/python3.8/site-packages/urllib3/connectionpool.py", line 703, in urlopen
    httplib_response = self._make_request(
  File "/opt/conda/lib/python3.8/site-packages/urllib3/connectionpool.py", line 386, in _make_request
    self._validate_conn(conn)
  File "/opt/conda/lib/python3.8/site-packages/urllib3/connectionpool.py", line 1042, in _validate_conn
    conn.connect()
  File "/opt/conda/lib/python3.8/site-packages/urllib3/connection.py", line 414, in connect
    self.sock = ssl_wrap_socket(
  File "/opt/conda/lib/python3.8/site-packages/urllib3/util/ssl_.py", line 449, in ssl_wrap_socket
    ssl_sock = _ssl_wrap_socket_impl(
  File "/opt/conda/lib/python3.8/site-packages/urllib3/util/ssl_.py", line 493, in _ssl_wrap_socket_impl
    return ssl_context.wrap_socket(sock, server_hostname=server_hostname)
  File "/opt/conda/lib/python3.8/ssl.py", line 500, in wrap_socket
    return self.sslsocket_class._create(
  File "/opt/conda/lib/python3.8/ssl.py", line 1040, in _create
    self.do_handshake()
  File "/opt/conda/lib/python3.8/ssl.py", line 1309, in do_handshake
    self._sslobj.do_handshake()
ssl.SSLEOFError: EOF occurred in violation of protocol (_ssl.c:1131)

During handling of the above exception, another exception occurred:

Traceback (most recent call last):
  File "/opt/conda/lib/python3.8/site-packages/requests/adapters.py", line 489, in send
    resp = conn.urlopen(
  File "/opt/conda/lib/python3.8/site-packages/urllib3/connectionpool.py", line 787, in urlopen
    retries = retries.increment(
  File "/opt/conda/lib/python3.8/site-packages/urllib3/util/retry.py", line 592, in increment
    raise MaxRetryError(_pool, url, error or ResponseError(cause))
urllib3.exceptions.MaxRetryError: HTTPSConnectionPool(host='huggingface.co', port=443): Max retries exceeded with url: /meta-llama/Llama-2-7b-h/resolve/main/tokenizer_config.json (Caused by SSLError(SSLEOFError(8, 'EOF occurred in violation of protocol (_ssl.c:1131)')))

During handling of the above exception, another exception occurred:

Traceback (most recent call last):
  File "src/generate_dummy_article.py", line 43, in main
    tokenizer = AutoTokenizer.from_pretrained(config.model_name, user_auth_token=huggingface_token)
  File "/opt/conda/lib/python3.8/site-packages/transformers/models/auto/tokenization_auto.py", line 677, in from_pretrained
    tokenizer_config = get_tokenizer_config(pretrained_model_name_or_path, **kwargs)
  File "/opt/conda/lib/python3.8/site-packages/transformers/models/auto/tokenization_auto.py", line 510, in get_tokenizer_config
    resolved_config_file = cached_file(
  File "/opt/conda/lib/python3.8/site-packages/transformers/utils/hub.py", line 428, in cached_file
    resolved_file = hf_hub_download(
  File "/opt/conda/lib/python3.8/site-packages/huggingface_hub/utils/_validators.py", line 118, in _inner_fn
    return fn(*args, **kwargs)
  File "/opt/conda/lib/python3.8/site-packages/huggingface_hub/file_download.py", line 1195, in hf_hub_download
    metadata = get_hf_file_metadata(
  File "/opt/conda/lib/python3.8/site-packages/huggingface_hub/utils/_validators.py", line 118, in _inner_fn
    return fn(*args, **kwargs)
  File "/opt/conda/lib/python3.8/site-packages/huggingface_hub/file_download.py", line 1532, in get_hf_file_metadata
    r = _request_wrapper(
  File "/opt/conda/lib/python3.8/site-packages/huggingface_hub/file_download.py", line 407, in _request_wrapper
    response = _request_wrapper(
  File "/opt/conda/lib/python3.8/site-packages/huggingface_hub/file_download.py", line 442, in _request_wrapper
    return http_backoff(
  File "/opt/conda/lib/python3.8/site-packages/huggingface_hub/utils/_http.py", line 258, in http_backoff
    response = session.request(method=method, url=url, **kwargs)
  File "/opt/conda/lib/python3.8/site-packages/requests/sessions.py", line 587, in request
    resp = self.send(prep, **send_kwargs)
  File "/opt/conda/lib/python3.8/site-packages/requests/sessions.py", line 701, in send
    r = adapter.send(request, **kwargs)
  File "/opt/conda/lib/python3.8/site-packages/huggingface_hub/utils/_http.py", line 63, in send
    return super().send(request, *args, **kwargs)
  File "/opt/conda/lib/python3.8/site-packages/requests/adapters.py", line 563, in send
    raise SSLError(e, request=request)
requests.exceptions.SSLError: (MaxRetryError("HTTPSConnectionPool(host='huggingface.co', port=443): Max retries exceeded with url: /meta-llama/Llama-2-7b-h/resolve/main/tokenizer_config.json (Caused by SSLError(SSLEOFError(8, 'EOF occurred in violation of protocol (_ssl.c:1131)')))"), '(Request ID: fe747dd7-384e-4845-a18c-f54ed8bfbaea)')

